<?xml version="1.0"?>
<robot xmlns:xacro="http://www.ros.org/wiki/xacro" >

    <xacro:include filename="inertial_macros.xacro"/>

    <material name="white">
        <color rgba="1 1 1 1 "/>
    </material >
    <material name="black">
        <color rgba="0 0 0 1 "/>
    </material >

    <!-- BASE_LINK -->
    <link name="base_link">
    </link>
    <!-- CHASSIS_LINK -->
    <joint name="chassis_join" type="fixed">
        <parent link="base_link"/>
        <child link="chassis"/>
        <origin xyz="-0.73 0.0 0.0"/>
    </joint>

    <link name="chassis">
        <visual>
            <origin xyz="0.48 0.0 0.345"/>
            <geometry>
                <box size="0.96 0.46 0.69"/>
            </geometry>
            <material name="white"/>
        </visual>
        <collision>
            <origin xyz="0.48 0.0 0.345"/>
            <geometry>
                <box size="0.96 0.46 0.69"/>
            </geometry>
        </collision>
        <xacro:inertial_box mass="40" x="0.96" y="0.46" z="0.69">
            <origin xyz="0.48 0.0 0.345" rpy="0 0 0"/>
        </xacro:inertial_box>
    </link>

    <gazebo reference="chassis">
        <material>Gazebo/White</material>
    </gazebo>

    <!-- LEFT_WHEEL_LINK -->
    <joint name="left_wheel_joint" type="continuous">
        <parent link="base_link"/>
        <child link="left_wheel"/>
        <origin xyz="0.0 0.175 0.0" rpy="-${pi/2} 0 0"/>
        <axis xyz="0 0 1"/>
    </joint>
    <link name="left_wheel">
        <visual>
            <origin xyz="0.0 0.0 0.0" rpy="0.0 0.0 0.0"/>
            <geometry>
                <cylinder radius="0.05" length="0.04"/>
            </geometry>
            <material name="black"/>
        </visual>
        <collision>
            <origin xyz="0.0 0.0 0.0" rpy="0.0 0.0 0.0"/>
            <geometry>
                <cylinder radius="0.05" length="0.04"/>
            </geometry>
        </collision>
        <xacro:inertial_cylinder mass="0.2" length="0.04" radius="0.05">
            <origin xyz="0 0 0" rpy="0 0 0"/>
        </xacro:inertial_cylinder>
    </link>

    <gazebo reference="left_wheel">
        <material>Gazebo/Black</material>
    </gazebo>

    <!-- RIGHT_WHEEL_LINK -->
    <joint name="right_wheel_joint" type="continuous">
        <parent link="base_link"/>
        <child link="right_wheel"/>
        <origin xyz="0.0 -0.175 0.0" rpy="${pi/2} 0 0"/>
        <axis xyz="0 0 -1"/>
    </joint>
    <link name="right_wheel">
        <visual>
            <origin xyz="0.0 0.0 0.0" rpy="0.0 0.0 0.0"/>
            <geometry>
                <cylinder radius="0.05" length="0.04"/>
            </geometry>
            <material name="black"/>
        </visual>
        <collision>
            <origin xyz="0.0 0.0 0.0" rpy="0.0 0.0 0.0"/>
            <geometry>
                <cylinder radius="0.05" length="0.04"/>
            </geometry>
        </collision>
        <xacro:inertial_cylinder mass="0.2" length="0.04" radius="0.05">
            <origin xyz="0 0 0" rpy="0 0 0"/>
        </xacro:inertial_cylinder>
    </link>

    <gazebo reference="right_wheel">
        <material>Gazebo/Black</material>
    </gazebo>

    <!-- CASTER_WHEEL_LINK -->
    <joint name="caster_wheel_joint" type="fixed">
        <parent link="chassis"/>
        <child link="caster_wheel"/>
        <origin xyz="0.24 0.0 0.0"/>
    </joint>
    <link name="caster_wheel">
        <visual>
            <geometry>
                <sphere radius="0.05"/>
            </geometry>
            <material name="black"/>
        </visual>
        <collision>
            <geometry>
                <sphere radius="0.05"/>
            </geometry>
        </collision>
        <xacro:inertial_sphere mass="0.2" radius="0.05">
            <origin xyz="0 0 0" rpy="0 0 0"/>
        </xacro:inertial_sphere>
    </link>

    <gazebo reference="caster_wheel">
        <material>Gazebo/Black</material>
        <mu1 value="0.001"/>
        <mu2 value="0.001"/>
    </gazebo>
</robot>